version: '3.3'

services:
  postgres:
    image: postgres:latest
    environment:
      POSTGRES_DB: test_task_tretyakov_iqgroup
      POSTGRES_USER: postgres
      POSTGRES_PASSWORD: новый_пароль
      POSTGRES_INITDB_ARGS: "--data-checksums"
    ports:
      - "5432:5432"
    volumes:
      - postgres_data:/var/lib/postgresql/data
      - ./init_db:/docker-entrypoint-initdb.d
    command: >
      postgres 
      -c logging_collector=on 
      -c log_destination=stderr 
      -c log_directory=/var/log/postgresql
    healthcheck:
      test: ["CMD-SHELL", "pg_isready -U postgres"]
      interval: 5s
      timeout: 5s
      retries: 5
    networks:
      - app_network

  backend:
    build:
      context: ./backend
      dockerfile: Dockerfile
    ports:
      - "3000:3000"
    environment:
      - PORT=3000
      - DATABASE_HOST=postgres
      - DATABASE_PORT=5432
      - DATABASE_USER=postgres
      - DATABASE_PASSWORD=новый_пароль
      - DATABASE_NAME=test_task_tretyakov_iqgroup
    depends_on:
      - postgres
    volumes:
      - ./backend:/usr/src/app
      - /usr/src/app/node_modules
    networks:
      - app_network
    extra_hosts:
      - "postgres:host-gateway"

  frontend:
    build:
      context: ./frontend
      dockerfile: Dockerfile
    ports:
      - "5173:5173"
    environment:
      - VITE_API_URL=http://backend:3000
    volumes:
      - ./frontend:/usr/src/app
      - /usr/src/app/node_modules
    depends_on:
      - backend
    networks:
      - app_network

volumes:
  postgres_data:
    driver: local

networks:
  app_network:
    driver: bridge